Workbook

Sheet Alunos Geral
A1: Nº | B1: Turma | C1: Statrup | D1: Estudante | H1: 1 | I1: 2 | J1: 3 | K1: 4 | L1: 5 | M1: 6 | N1: 7 | O1: 8 | P1: 9 | Q1: 10 | R1: 11 | S1: 12 | T1: 13 | U1: 14 | V1: 15 | W1: 16 | X1: 17 | Y1: 18 | Z1: 19 | AA1: 20
A2: 1 | B2: 3A | C2: 07390190 | D2: ANA | F2: =G2-C2 -> 7382801910 | G2: 07390192100 | H2: B | I2: B | J2: A | K2: B | L2: A | M2: C | N2: C | O2: D | P2: B | Q2: C | R2: E | S2: B | T2: D | U2: D | V2: A | W2: C | X2: E | Y2: B | Z2: C | AA2: B
A3: 2 | B3: 3A | C3: 71237655161 | D3: ANA CLARA | F3: =G3-C3 -> 0 | G3: 71237655161 | H3: C | I3: B | J3: A | K3: D | L3: B | M3: E | N3: C | O3: C | P3: D | Q3: E | R3: A | S3: C | T3: B | U3: D | V3: A | W3: B | X3: C | Y3: E | Z3: A | AA3: C
A4: 3 | B4: 3A | C4: 06302550165 | D4: ANA LUÍZA | F4: =G4-C4 -> 0 | G4: 06302550165 | H4: A | I4: B | J4: E | K4: B | L4: B | M4: B | N4: D | O4: D | P4: B | Q4: C | R4: E | S4: B | T4: D | U4: D | V4: C | W4: D | X4: D | Y4: D | Z4: D | AA4: B
A5: 4 | B5: 3A | C5: 09690873148 | D5: ANDREW LEONARDO LIMA SANTANA PEIXOTO | F5: =G5-C5 -> 0 | G5: 09690873148 | H5: A | I5: B | J5: C | K5: B | L5: B | M5: E | N5: D | O5: D | P5: B | Q5: C | R5: D | S5: B | T5: D | U5: E | V5: C | W5: E | X5: D | Y5: D | Z5: D | AA5: C
A6: 5 | B6: 3A | C6: 11313724173 | D6: ANITA GONÇALVES EVANGELISTA | F6: =G6-C6 -> 0 | G6: 11313724173 | H6: A | I6: B | J6: E | K6: B | L6: C | M6: A | N6: B | O6: D | P6: D | Q6: B | R6: E | S6: B | T6: D | U6: D | V6: C | W6: B | X6: E | Y6: B | Z6: D | AA6: B
A7: 6 | B7: 3A | C7: 09677691163 | D7: ARTHUR SENA GONÇALVES | F7: =G7-C7 -> -9677691163
A8: 7 | B8: 3A | C8: 04418461140 | D8: ARTHUR VITOR RODRIGUES NAZARO | F8: =G8-C8 -> 0 | G8: 04418461140 | H8: B | I8: B | J8: B | K8: B | L8: A | M8: C | N8: D | O8: C | P8: B | Q8: B | R8: E | S8: B | T8: D | U8: D | V8: C | W8: A | X8: C | Y8: B | Z8: A | AA8: B
A9: 8 | B9: 3A | C9: 08461753127 | D9: BEATRIZ NUNES DE CARVALHO | F9: =G9-C9 -> 0 | G9: 08461753127 | H9: B | I9: B | J9: D | K9: B | L9: A | M9: E | N9: D | O9: B | P9: B | Q9: C | R9: E | S9: B | T9: D | U9: D | V9: D | W9: B | X9: D | Y9: E | Z9: C | AA9: C
A10: 9 | B10: 3A | C10: 10283525142 | D10: BIANCA ALVES FREIRE | F10: =G10-C10 -> 0 | G10: 10283525142 | H10: A | I10: B | J10: B | K10: B | L10: B | M10: A | N10: A | O10: C | P10: B | Q10: C | R10: E | S10: B | T10: D | U10: A | V10: B | W10: A | X10: D | Y10: B | Z10: D | AA10: B
A11: 10 | B11: 3A | C11: 07491114105 | D11: CAIO QUEIROZ DE OLIVEIRA | F11: =G11-C11 -> 0 | G11: 07491114105 | H11: A | I11: A | J11: C | K11: B | L11: B | M11: B | N11: C | O11: D | P11: B | Q11: C | R11: E | S11: B | T11: D | U11: E | V11: C | W11: E | X11: D | Y11: D | Z11: C | AA11: B
A12: 11 | B12: 3A | C12: 08877303107 | D12: DANIELE ALVES DE SOUZA | F12: =G12-C12 -> 0 | G12: 08877303107 | H12: B | I12: B | J12: C | K12: B | L12: B | M12: B | N12: A | O12: B | P12: A | Q12: C | R12: E | S12: B | T12: D | U12: D | V12: C | W12: B | X12: D | Y12: E | Z12: B | AA12: A
A13: 12 | B13: 3A | C13: 05819746112 | D13: GIULIANO MAGALHÃES OLIVEIRA | F13: =G13-C13 -> 0 | G13: 05819746112 | H13: C | I13: A | J13: D | K13: B | L13: E | M13: C | N13: D | O13: C | P13: B | Q13: E | R13: E | S13: B | T13: D | U13: E | V13: C | W13: B | X13: D | Y13: B | Z13: D | AA13: A
A14: 13 | B14: 3A | C14: 09076952132 | D14: GUILHERME CAMPOS ROJAS | F14: =G14-C14 -> 0 | G14: 09076952132 | H14: D | I14: B | J14: E | K14: B | L14: A | M14: A | N14: B | O14: B | P14: B | Q14: C | R14: E | S14: B | T14: D | U14: E | V14: C | W14: B | X14: D | Y14: E | Z14: A | AA14: E
A15: 14 | B15: 3A | C15: 08186780114 | D15: GUILHERME DE SOUSA SILVA | F15: =G15-C15 -> 0 | G15: 08186780114 | H15: D | I15: C | J15: E | K15: B | L15: B | M15: B | N15: B | O15: D | P15: B | Q15: D | R15: E | S15: E | T15: C | U15: E | V15: A | W15: E | X15: D | Y15: B | Z15: D | AA15: B
A16: 15 | B16: 3A | C16: 05732953108 | D16: HEITOR ROCHA MOREIRA | F16: =G16-C16 -> 0 | G16: 05732953108 | H16: B | I16: B | J16: A | K16: B | L16: E | M16: C | N16: C | O16: D | P16: B | Q16: A | R16: E | S16: B | T16: D | U16: D | V16: A | W16: B | X16: D | Y16: A | Z16: E | AA16: A
A17: 16 | B17: 3A | C17: 08695966160 | D17: IZABELLE LETICIA SANTIAGO SOUZA | F17: =G17-C17 -> 0 | G17: 08695966160 | H17: B | I17: B | J17: D | K17: B | L17: B | M17: C | N17: E | O17: B | P17: B | Q17: C | R17: D | S17: B | T17: D | U17: B | V17: C | W17: C | X17: D | Y17: D | Z17: E | AA17: E
A18: 17 | B18: 3A | C18: 06430383105 | D18: JOÃO PEDRO FIGUEIRÊDO PEREIRA DE SOUZA E SILVA | F18: =G18-C18 -> 0 | G18: 06430383105 | H18: E | I18: E | J18: A | K18: D | L18: C | M18: B | N18: D | O18: D | P18: B | Q18: C | R18: E | S18: B | T18: D | U18: E | V18: A | W18: D | X18: D | Y18: B | Z18: D | AA18: A
A19: 18 | B19: 3A | C19: 06795468127 | D19: JOÃO PEDRO TORRES SILVA | F19: =G19-C19 -> 0 | G19: 06795468127 | H19: B | I19: B | J19: C | K19: B | L19: E | M19: D | N19: E | O19: C | P19: A | Q19: C | R19: E | S19: B | T19: C | U19: D | V19: A | W19: E | X19: D | Y19: E | Z19: A | AA19: A
... A38: 37 | B38: 3A | C38: 08661908132 | D38: THIAGO PEREIRA CASTRO | F38: =G38-C38 -> 0 | G38: 08661908132 | H38: B | I38: B | J38: C | K38: B | L38: B | M38: B | N38: D | O38: D | P38: B | Q38: C | R38: E | S38: B | T38: D | U38: D | V38: A | W38: E | X38: D | Y38: D | Z38: A | AA38: B
A39: 38 | B39: 3A | C39: 09019945106 | D39: YASMIN CARDOSO RIBEIRO | F39: =G39-C39 -> -9019945106
A40: 1 | B40: 3B | C40: 05793405119 | D40: AMANDA RODRIGUES GOUVEIA | F40: =G40-C40 -> 0 | G40: 05793405119 | I40: B | K40: B | L40: C | M40: A | N40: B | P40: B | Q40: C | R40: E | T40: D | V40: D | W40: C | X40: D | Y40: D | Z40: D
A41: 2 | B41: 3B | C41: 09868770181 | D41: ANA CECÍLIA DE SOUSA LIMA | F41: =G41-C41 -> -9868770181
A42: 3 | B42: 3B | C42: 08542442121 | D42: ANA CLARA MADSON DE BRITO SANTOS | F42: =G42-C42 -> 0 | G42: 08542442121 | H42: B | I42: A | J42: E | K42: B | L42: B | M42: A | N42: E | O42: D | P42: B | Q42: C | R42: E | S42: B | T42: D | U42: A | V42: C | W42: E | X42: D | Y42: B | Z42: E | AA42: E
A43: 4 | B43: 3B | C43: 07887980143 | D43: ANA JULIA JUSTINO FERREIRA DO NASCIMENTO | F43: =G43-C43 -> 0 | G43: 07887980143 | H43: C | I43: B | J43: D | K43: B | L43: E | M43: B | N43: D | O43: D | P43: C | Q43: C | R43: E | S43: B | T43: D | U43: D | V43: B | W43: B | X43: D | Y43: E | Z43: D | AA43: E
A44: 5 | B44: 3B | C44: 06238713194 | D44: ANA LUÍZA ARAÚJO MACIEL | F44: =G44-C44 -> 0 | G44: 06238713194 | H44: D | I44: B | J44: B | K44: B | L44: B | M44: D | N44: C | O44: B | P44: E | Q44: C | R44: E | S44: B | T44: D | U44: C | V44: C | W44: D | X44: D | Y44: C | Z44: D | AA44: E
A45: 6 | B45: 3B | C45: 08245489140 | D45: ANNA LUIZA LINO ASSUNÇÃO | F45: =G45-C45 -> 0 | G45: 08245489140 | H45: A | I45: B | J45: C | K45: B | L45: E | M45: B | N45: C | O45: B | P45: B | Q45: A | R45: B | S45: B | T45: D | U45: C | V45: C | W45: E | X45: C | Y45: D | Z45: E | AA45: C
A46: 7 | B46: 3B | C46: 09181777159 | D46: ARTHUR SILVA SOARES | F46: =G46-C46 -> -9181777159
A47: 8 | B47: 3B | C47: 05813521143 | D47: ÁTHYLA ARAÚJO DO NASCIMENTO | F47: =G47-C47 -> 0 | G47: 05813521143 | H47: A | I47: B | J47: D | K47: B | L47: E | M47: B | N47: D | O47: D | P47: B | Q47: C | R47: E | S47: B | T47: D | U47: D | V47: A | W47: E | X47: D | Y47: E | Z47: D | AA47: B
A48: 9 | B48: 3B | C48: 08500476176 | D48: BRUNO FERREIRA DA SILVA | F48: =G48-C48 -> 0 | G48: 08500476176 | H48: A | I48: B | J48: C | K48: B | L48: B | M48: B | N48: D | O48: D | P48: B | Q48: C | R48: E | S48: B | T48: D | U48: D | V48: C | W48: E | X48: D | Y48: D | Z48: D | AA48: C
A49: 10 | B49: 3B | C49: 08384942188 | D49: CAUÃ DA ROCHA SOUSA | F49: =G49-C49 -> 0 | G49: 08384942188 | H49: B | I49: B | J49: A | K49: B | L49: B | M49: D | N49: C | O49: B | P49: C | Q49: C | R49: E | S49: B | T49: D | U49: B | V49: A | W49: B | X49: D | Y49: B | Z49: E | AA49: E
A50: 11 | B50: 3B | C50: 07090733130 | D50: DANIEL CARVALHO DE OLIVEIRA | F50: =G50-C50 -> 0 | G50: 07090733130 | H50: A | I50: B | J50: C | K50: B | L50: B | M50: A | N50: D | O50: D | P50: B | Q50: C | R50: E | S50: B | T50: D | U50: D | V50: C | W50: E | X50: D | Y50: B | Z50: D | AA50: B
A51: 12 | B51: 3B | C51: 04047837164 | D51: DAVI TAVARES DE MORAIS | F51: =G51-C51 -> 0 | G51: 04047837164 | H51: A | I51: D | J51: C | K51: C | L51: E | M51: B | N51: D | O51: B | P51: B | Q51: D | R51: E | S51: B | T51: A | U51: D | V51: D | W51: C | X51: D | Y51: B | Z51: A | AA51: C
A52: 13 | B52: 3B | C52: 70967097118 | D52: ESTHER VARGAS DORNELES | F52: =G52-C52 -> -70967097118
A53: 14 | B53: 3B | C53: 08970355189 | D53: GUSTAVO MACIEL LOPES | F53: =G53-C53 -> 0 | G53: 08970355189 | H53: C | I53: B | J53: C | K53: A | L53: E | M53: C | N53: D | O53: C | P53: E | Q53: B | R53: B | S53: B | T53: D | U53: E | V53: D | W53: B | X53: D | Y53: B | Z53: E | AA53: E
A54: 15 | B54: 3B | C54: 07965349183 | D54: HELLOA SAMILLE RODRIGUES DOS SANTOS | F54: =G54-C54 -> 0 | G54: 07965349183 | H54: C | I54: B | J54: D | K54: B | L54: E | M54: A | N54: B | O54: C | P54: A | Q54: B | R54: E | S54: B | T54: D | U54: D | V54: C | W54: D | X54: D | Y54: B | Z54: D | AA54: B
A55: 16 | B55: 3B | C55: 08543142105 | D55: HELOÍSA SOUZA FERNANDES | F55: =G55-C55 -> 0 | G55: 08543142105 | H55: D | I55: C | J55: E | K55: B | L55: B | M55: C | N55: D | O55: C | P55: D | Q55: A | R55: B | S55: E | T55: B | U55: C | V55: E | W55: B | X55: C | Y55: D | Z55: A | AA55: A
A56: 17 | B56: 3B | C56: 10237382105 | D56: HIASMIM BENTO DA SILVA | F56: =G56-C56 -> 0 | G56: 10237382105 | H56: A | I56: B | J56: E | K56: B | L56: E | M56: B | N56: D | O56: D | P56: B | Q56: C | R56: E | S56: B | T56: D | U56: C | V56: C | W56: B | X56: D | Y56: E | Z56: D | AA56: E
A57: 18 | B57: 3B | C57: 05536817108 | D57: HUGO BOAVENTURA SILVA ARAUJO | F57: =G57-C57 -> 0 | G57: 05536817108 | H57: A | I57: B | J57: C | K57: B | L57: B | M57: A | N57: D | O57: B | P57: C | Q57: C | R57: E | S57: B | T57: D | U57: D | V57: C | W57: D | X57: D | Y57: E | Z57: D | AA57: E
A58: 19 | B58: 3B | C58: 04760434178 | D58: ISABELLA SANTOS SEABRA | F58: =G58-C58 -> 0 | G58: 04760434178 | H58: B | I58: A | J58: E | K58: B | L58: E | M58: C | N58: B | O58: D | P58: B | Q58: A | R58: E | S58: B | T58: C | U58: D | V58: A | W58: E | X58: D | Y58: B | Z58: A | AA58: C
...

Sheet ERROS!

Sheet 3A
A1: 3A (36) | D1: NOTA | E1: SIMULADO SAEB MATEMÁTICA 01/09 (SEGUNDA-FEIRA)
A2: Nº | B2: CPF | C2: NOME | E2: 1 | F2: 2 | G2: 3 | H2: 4 | I2: 5 | J2: 6 | K2: 7 | L2: 8 | M2: 9 | N2: 10 | O2: 11 | P2: 12 | Q2: 13 | R2: 14 | S2: 15 | T2: 16 | U2: 17 | V2: 18 | W2: 19 | X2: 20
A3: 00 | B3: 00000000000 | C3: GABARITO | E3: A | F3: B | G3: C | H3: B | I3: B | J3: B | K3: D | L3: D | M3: B | N3: C | O3: E | P3: B | Q3: D | R3: E | S3: C | T3: ## | U3: D | V3: D | W3: D | X3: C
A4: VALORES | E4: 0.5 | F4: 0.5 | G4: 0.5 | H4: 0.5 | I4: 0.5 | J4: 0.5 | K4: 0.5 | L4: 0.5 | M4: 0.5 | N4: 0.5 | O4: 0.5 | P4: 0.5 | Q4: 0.5 | R4: 0.5 | S4: 0.5 | T4: 0.5 | U4: 0.5 | V4: 0.5 | W4: 0.5 | X4: 0.5
A5: TESTE | D5: =B63 -> 10 | E5: A | F5: B | G5: C | H5: B | I5: B | J5: B | K5: D | L5: D | M5: B | N5: C | O5: E | P5: B | Q5: D | R5: E | S5: C | T5: ## | U5: D | V5: D | W5: D | X5: C
A6: 1 | B6: 07390192100 | C6: ANA CLARA BATISTA | D6: =B64 -> 4.5 | E6: B | F6: B | G6: A | H6: B | I6: A | J6: C | K6: C | L6: D | M6: B | N6: C | O6: E | P6: B | Q6: D | R6: D | S6: A | T6: ## | U6: E | V6: B | W6: C | X6: B
A7: 2 | B7: 71237655161 | C7: ANA CLARA MACIEL FARIAS | D7: =B65 -> 2 | E7: C | F7: B | G7: A | H7: D | I7: B | J7: E | K7: C | L7: C | M7: D | N7: E | O7: A | P7: C | Q7: B | R7: D | S7: A | T7: ## | U7: C | V7: E | W7: A | X7: C
A8: 3 | B8: 06302550165 | C8: ANA LUÍZA ABRANTE DOS SANTOS | D8: =B66 -> 8.5 | E8: A | F8: B | G8: E | H8: B | I8: B | J8: B | K8: D | L8: D | M8: B | N8: C | O8: E | P8: B | Q8: D | R8: D | S8: C | T8: ## | U8: D | V8: D | W8: D | X8: B
A9: 4 | B9: 09690873148 | C9: ANDREW LEONARDO LIMA SANTANA PEIXOTO | D9: =B67 -> 9 | E9: A | F9: B | G9: C | H9: B | I9: B | J9: E | K9: D | L9: D | M9: B | N9: C | O9: D | P9: B | Q9: D | R9: E | S9: C | T9: ## | U9: D | V9: D | W9: D | X9: C
A10: 5 | B10: 11313724173 | C10: ANITA GONÇALVES EVANGELISTA | D10: =B68 -> 5 | E10: A | F10: B | G10: E | H10: B | I10: C | J10: A | K10: B | L10: D | M10: D | N10: B | O10: E | P10: B | Q10: D | R10: D | S10: C | T10: ## | U10: E | V10: B | W10: D | X10: B
A11: 6 | B11: 09677691163 | C11: ARTHUR SENA GONÇALVES
A12: 7 | B12: 04418461140 | C12: ARTHUR VITOR RODRIGUES NAZARO | D12: =B70 -> 4.5 | E12: B | F12: B | G12: B | H12: B | I12: A | J12: C | K12: D | L12: C | M12: B | N12: B | O12: E | P12: B | Q12: D | R12: D | S12: C | T12: ## | U12: C | V12: B | W12: A | X12: B
A13: 8 | B13: 08461753127 | C13: BEATRIZ NUNES DE CARVALHO | D13: =B71 -> 5.5 | E13: B | F13: B | G13: D | H13: B | I13: A | J13: E | K13: D | L13: B | M13: B | N13: C | O13: E | P13: B | Q13: D | R13: D | S13: D | T13: ## | U13: D | V13: E | W13: C | X13: C
A14: 9 | B14: 10283525142 | C14: BIANCA ALVES FREIRE | D14: =B72 -> 6 | E14: A | F14: B | G14: B | H14: B | I14: B | J14: A | K14: A | L14: C | M14: B | N14: C | O14: E | P14: B | Q14: D | R14: A | S14: B | T14: ## | U14: D | V14: B | W14: D | X14: B
A15: 10 | B15: 07491114105 | C15: CAIO QUEIROZ DE OLIVEIRA | D15: =B73 -> 8 | E15: A | F15: A | G15: C | H15: B | I15: B | J15: B | K15: C | L15: D | M15: B | N15: C | O15: E | P15: B | Q15: D | R15: E | S15: C | T15: ## | U15: D | V15: D | W15: C | X15: B
A16: 11 | B16: 08877303107 | C16: DANIELE ALVES DE SOUZA | D16: =B74 -> 6 | E16: B | F16: B | G16: C | H16: B | I16: B | J16: B | K16: A | L16: B | M16: A | N16: C | O16: E | P16: B | Q16: D | R16: D | S16: C | T16: ## | U16: D | V16: E | W16: B | X16: A
A17: 12 | B17: 05819746112 | C17: GIULIANO MAGALHÃES OLIVEIRA | D17: =B75 -> 5.5 | E17: C | F17: A | G17: D | H17: B | I17: E | J17: C | K17: D | L17: C | M17: B | N17: E | O17: E | P17: B | Q17: D | R17: E | S17: C | T17: ## | U17: D | V17: B | W17: D | X17: A
A18: 13 | B18: 09076952132 | C18: GUILHERME CAMPOS ROJAS | D18: =B76 -> 5.5 | E18: D | F18: B | G18: E | H18: B | I18: A | J18: A | K18: B | L18: B | M18: B | N18: C | O18: E | P18: B | Q18: D | R18: E | S18: C | T18: ## | U18: D | V18: E | W18: A | X18: E
A19: 14 | B19: 08186780114 | C19: GUILHERME DE SOUSA SILVA | D19: =B77 -> 5 | E19: D | F19: C | G19: E | H19: B | I19: B | J19: B | K19: B | L19: D | M19: B | N19: D | O19: E | P19: E | Q19: C | R19: E | S19: A | T19: ## | U19: D | V19: B | W19: D | X19: B
A20: 15 | B20: 05732953108 | C20: HEITOR ROCHA MOREIRA | D20: =B78 -> 4.5 | E20: B | F20: B | G20: A | H20: B | I20: E | J20: C | K20: C | L20: D | M20: B | N20: A | O20: E | P20: B | Q20: D | R20: D | S20: A | T20: ## | U20: D | V20: A | W20: E | X20: A
A21: 16 | B21: 08695966160 | C21: IZABELLE LETICIA SANTIAGO SOUZA | D21: =B79 -> 5.5 | E21: B | F21: B | G21: D | H21: B | I21: B | J21: C | K21: E | L21: B | M21: B | N21: C | O21: D | P21: B | Q21: D | R21: B | S21: C | T21: ## | U21: D | V21: D | W21: E | X21: E
A22: 17 | B22: 06430383105 | C22: JOÃO PEDRO FIGUEIRÊDO PEREIRA DE SOUZA E SILVA | D22: =B80 -> 6 | E22: E | F22: E | G22: A | H22: D | I22: C | J22: B | K22: D | L22: D | M22: B | N22: C | O22: E | P22: B | Q22: D | R22: E | S22: A | T22: ## | U22: D | V22: B | W22: D | X22: A
A23: 18 | B23: 06795468127 | C23: JOÃO PEDRO TORRES SILVA | D23: =B81 -> 4 | E23: B | F23: B | G23: C | H23: B | I23: E | J23: D | K23: E | L23: C | M23: A | N23: C | O23: E | P23: B | Q23: C | R23: D | S23: A | T23: ## | U23: D | V23: E | W23: A | X23: A
... A42: 37 | B42: 08661908132 | C42: THIAGO PEREIRA CASTRO | D42: =B100 -> 7.5 | E42: B | F42: B | G42: C | H42: B | I42: B | J42: B | K42: D | L42: D | M42: B | N42: C | O42: E | P42: B | Q42: D | R42: D | S42: A | T42: ## | U42: D | V42: D | W42: A | X42: B
A43: 38 | B43: 09019945106 | C43: YASMIN CARDOSO RIBEIRO
C44: MÉDIA GERAL DA TURMA | D44: =B102 -> 5.5142857
C45: ACERTOS | E45: =COUNTIF(E6:E43,"A") -> 10 | F45: =COUNTIF(F6:F43,"B") -> 25 | G45: =COUNTIF(G6:G43,"C") -> 7 | H45: =COUNTIF(H6:H43,"B") -> 32 | I45: =COUNTIF(I6:I43,"B") -> 13 | J45: =COUNTIF(J6:J43,"B") -> 12 | K45: =COUNTIF(K6:K43,"D") -> 18 | L45: =COUNTIF(L6:L43,"D") -> 18 | M45: =COUNTIF(M6:M43,"B") -> 27 | N45: =COUNTIF(N6:N43,"C") -> 18 | O45: =COUNTIF(O6:O43,"E") -> 27 | P45: =COUNTIF(P6:P43,"B") -> 33 | Q45: =COUNTIF(Q6:Q43,"D") -> 29 | R45: =COUNTIF(R6:R43,"E") -> 8 | S45: =COUNTIF(S6:S43,"C") -> 15 | T45: =COUNTIF(T6:T43,"##") -> 35 | U45: =COUNTIF(U6:U43,"D") -> 27 | V45: =COUNTIF(V6:V43,"D") -> 11 | W45: =COUNTIF(W6:W43,"D") -> 12 | X45: =COUNTIF(X6:X43,"C") -> 9
C46: ACERTOS (%) | E46: =(E45)/36 -> 0.27777778 | F46: =(F45)/36 -> 0.69444444 | G46: =(G45)/36 -> 0.19444444 | H46: =(H45)/36 -> 0.88888889 | I46: =(I45)/36 -> 0.36111111 | J46: =(J45)/36 -> 0.33333333 | K46: =(K45)/36 -> 0.5 | L46: =(L45)/36 -> 0.5 | ... X46: =(X45)/36 -> 0.25
C47: ERROS | E47: =36-E45 -> 26 | F47: =36-F45 -> 11 | G47: =36-G45 -> 29 | H47: =36-H45 -> 4 | I47: =36-I45 -> 23 | J47: =36-J45 -> 24 | K47: =36-K45 -> 18 | L47: =36-L45 -> 18 | ... X47: =36-X45 -> 27
C48: ERROS (%) | E48: =100%-E46 -> 0.72222222 | F48: =100%-F46 -> 0.30555556 | G48: =100%-G46 -> 0.80555556 | H48: =100%-H46 -> 0.11111111 | I48: =100%-I46 -> 0.63888889 | J48: =100%-J46 -> 0.66666667 | K48: =100%-K46 -> 0.5 | L48: =100%-L46 -> 0.5 | ... X48: =100%-X46 -> 0.75
C49: PARTICIPAÇÃO DA TURMA (%) | E49: =(36/38) -> 0.94736842
C50: GERAL (%) | E50: =(E45+'3B'!E45+'3C'!E43+'3D'!E42)/137 -> 0.23357664 | F50: =(F45+'3B'!F45+'3C'!F43+'3D'!F42)/137 -> 0.74452555 | G50: =(G45+'3B'!G45+'3C'!G43+'3D'!G42)/137 -> 0.18248175 | H50: =(H45+'3B'!H45+'3C'!H43+'3D'!H42)/137 -> 0.88321168 | I50: =(I45+'3B'!I45+'3C'!I43+'3D'!I42)/137 -> 0.27737226 | J50: =(J45+'3B'!J45+'3C'!J43+'3D'!J42)/137 -> 0.30656934 | K50: =(K45+'3B'!K45+'3C'!K43+'3D'!K42)/137 -> 0.43065693 | L50: =(L45+'3B'!L45+'3C'!L43+'3D'!L42)/137 -> 0.50364964 | ... W50: =(W45+'3B'!W45+'3C'!W43+'3D'!W42)/137 -> 0.37226277 | X50: =(X45+'3B'!X45+'3C'!X43+'3D'!X42)/136 -> 0.22794118
C52: ESTUDANTES DA SALA DE RECURSOS | G52: OK | H52: LANÇAR O GABARITO COM O VALOR DAS QUESTÕES
C53: ESTUDANTES ANTENDIDOS PELA ORIENTAÇÃO | G53: OK | H53: EDITAR "FORMATAÇÃO CONDICIONAL" NA PLANILHA DE RESPOSTAS E TESTE
C54: QUESTÕES LÍNGUA MATEMÁTICA | G54: OK | H54: EDITAR PORCENTAGENS DE ERROS E ACERTOS
G55: OK | H55: EITAR "FORMATAÇÃO CONDICIONAL" DE VALORES NA PLANILHA DE NOTAS
G56: OK | H56: EDITAR QUANTIDADE DE ESTUDANTES
A62: Nº | B62: NOTA | C62: NOME | D62: N | E62: 1 | F62: 2 | G62: 3 | H62: 4 | I62: 5 | J62: 6 | K62: 7 | L62: 8 | M62: 9 | N62: 10 | O62: 11 | P62: 12 | Q62: 13 | R62: 14 | S62: 15 | T62: 16 | U62: 17 | V62: 18 | W62: 19 | X62: 20
A63: 00 | B63: =SUM(E63:X63) -> 10 | C63: GABARITO | D63: =B63 -> 10 | E63: =IF(E5=$E$3,$E$4,0) -> 0.5 | F63: =IF(F5=$F$3,$F$4,0) -> 0.5 | G63: =IF(G5=$G$3,$G$4,0) -> 0.5 | H63: =IF(H5=$H$3,$H$4,0) -> 0.5 | I63: =IF(I5=$I$3,$I$4,0) -> 0.5 | J63: =IF(J5=$J$3,$J$4,0) -> 0.5 | K63: =IF(K5=$K$3,$K$4,0) -> 0.5 | L63: =IF(L5=$L$3,$L$4,0) -> 0.5 | M63: =IF(M5=$M$3,$M$4,0) -> 0.5 | N63: =IF(N5=$N$3,$N$4,0) -> 0.5 | O63: =IF(O5=$O$3,$O$4,0) -> 0.5 | P63: =IF(P5=$P$3,$P$4,0) -> 0.5 | Q63: =IF(Q5=$Q$3,$Q$4,0) -> 0.5 | R63: =IF(R5=$R$3,$R$4,0) -> 0.5 | S63: =IF(S5=$S$3,$S$4,0) -> 0.5 | T63: =IF(T5=$T$3,$T$4,0) -> 0.5 | U63: =IF(U5=$U$3,$U$4,0) -> 0.5 | V63: =IF(V5=$V$3,$V$4,0) -> 0.5 | W63: =IF(W5=$W$3,$W$4,0) -> 0.5 | X63: =IF(X5=$X$3,$X$4,0) -> 0.5
A64: 1 | B64: =SUM(E64:X64) -> 4.5 | C64: ANA CLARA BATISTA | D64: =B64 -> 4.5 | E64: =IF(E6=$E$3,$E$4,0) -> 0 | F64: =IF(F6=$F$3,$F$4,0) -> 0.5 | G64: =IF(G6=$G$3,$G$4,0) -> 0 | H64: =IF(H6=$H$3,$H$4,0) -> 0.5 | I64: =IF(I6=$I$3,$I$4,0) -> 0 | J64: =IF(J6=$J$3,$J$4,0) -> 0 | K64: =IF(K6=$K$3,$K$4,0) -> 0 | L64: =IF(L6=$L$3,$L$4,0) -> 0.5 | M64: =IF(M6=$M$3,$M$4,0) -> 0.5 | N64: =IF(N6=$N$3,$N$4,0) -> 0.5 | O64: =IF(O6=$O$3,$O$4,0) -> 0.5 | P64: =IF(P6=$P$3,$P$4,0) -> 0.5 | Q64: =IF(Q6=$Q$3,$Q$4,0) -> 0.5 | R64: =IF(R6=$R$3,$R$4,0) -> 0 | S64: =IF(S6=$S$3,$S$4,0) -> 0 | T64: =IF(T6=$T$3,$T$4,0) -> 0.5 | U64: =IF(U6=$U$3,$U$4,0) -> 0 | V64: =IF(V6=$V$3,$V$4,0) -> 0 | W64: =IF(W6=$W$3,$W$4,0) -> 0 | X64: =IF(X6=$X$3,$X$4,0) -> 0
...

Sheet 3B
A1: 3B (34) | D1: NOTA | E1: SIMULADO SAEB MATEMÁTICA 01/09 (SEGUNDA-FEIRA)
A2: Nº | B2: CPF | C2: NOME | E2: 1 | F2: 2 | G2: 3 | H2: 4 | I2: 5 | J2: 6 | K2: 7 | L2: 8 | M2: 9 | N2: 10 | O2: 11 | P2: 12 | Q2: 13 | R2: 14 | S2: 15 | T2: 16 | U2: 17 | V2: 18 | W2: 19 | X2: 20
A3: 00 | B3: 00000000000 | C3: GABARITO | E3: A | F3: B | G3: C | H3: B | I3: B | J3: B | K3: D | L3: D | M3: B | N3: C | O3: E | P3: B | Q3: D | R3: E | S3: C | T3: ## | U3: D | V3: D | W3: D | X3: C
A4: VALORES | E4: 0.5 | F4: 0.5 | G4: 0.5 | H4: 0.5 | I4: 0.5 | J4: 0.5 | K4: 0.5 | L4: 0.5 | M4: 0.5 | N4: 0.5 | O4: 0.5 | P4: 0.5 | Q4: 0.5 | R4: 0.5 | S4: 0.5 | T4: 0.5 | U4: 0.5 | V4: 0.5 | W4: 0.5 | X4: 0.5
A5: TESTE | D5: =B63 -> 10 | E5: A | F5: B | G5: C | H5: B | I5: B | J5: B | K5: D | L5: D | M5: B | N5: C | O5: E | P5: B | Q5: D | R5: E | S5: C | T5: ## | U5: D | V5: D | W5: D | X5: C
A6: 1 | B6: 05793405119 | C6: AMANDA RODRIGUES GOUVEIA | D6: =B64 -> 5 | F6: B | H6: B | I6: C | J6: A | K6: B | M6: B | N6: C | O6: E | Q6: D | S6: D | T6: ## | U6: D | V6: D | W6: D
A7: 2 | B7: 09868770181 | C7: ANA CECÍLIA DE SOUSA LIMA
A8: 3 | B8: 08542442121 | C8: ANA CLARA MADSON DE BRITO SANTOS | D8: =B66 -> 5.5 | E8: B | F8: A | G8: E | H8: B | I8: B | J8: A | K8: E | L8: D | M8: B | N8: C | O8: E | P8: B | Q8: D | R8: A | S8: C | T8: ## | U8: D | V8: B | W8: E | X8: E
A9: 4 | B9: 07887980143 | C9: ANA JULIA JUSTINO FERREIRA DO NASCIMENTO | D9: =B67 -> 6 | E9: C | F9: B | G9: D | H9: B | I9: E | J9: B | K9: D | L9: D | M9: C | N9: C | O9: E | P9: B | Q9: D | R9: D | S9: B | T9: ## | U9: D | V9: E | W9: D | X9: E
A10: 5 | B10: 06238713194 | C10: ANA LUÍZA ARAÚJO MACIEL | D10: =B68 -> 5.5 | E10: D | F10: B | G10: B | H10: B | I10: B | J10: D | K10: C | L10: B | M10: E | N10: C | O10: E | P10: B | Q10: D | R10: C | S10: C | T10: ## | U10: D | V10: C | W10: D | X10: E
A11: 6 | B11: 08245489140 | C11: ANNA LUIZA LINO ASSUNÇÃO | D11: =B69 -> 6 | E11: A | F11: B | G11: C | H11: B | I11: E | J11: B | K11: C | L11: B | M11: B | N11: A | O11: B | P11: B | Q11: D | R11: C | S11: C | T11: ## | U11: C | V11: D | W11: E | X11: C
A12: 7 | B12: 09181777159 | C12: ARTHUR SILVA SOARES
A13: 8 | B13: 05813521143 | C13: ÁTHYLA ARAÚJO DO NASCIMENTO | D13: =B71 -> 7 | E13: A | F13: B | G13: D | H13: B | I13: E | J13: B | K13: D | L13: D | M13: B | N13: C | O13: E | P13: B | Q13: D | R13: D | S13: A | T13: ## | U13: D | V13: E | W13: D | X13: B
A14: 9 | B14: 08500476176 | C14: BRUNO FERREIRA DA SILVA | D14: =B72 -> 9.5 | E14: A | F14: B | G14: C | H14: B | I14: B | J14: B | K14: D | L14: D | M14: B | N14: C | O14: E | P14: B | Q14: D | R14: D | S14: C | T14: ## | U14: D | V14: D | W14: D | X14: C
A15: 10 | B15: 08384942188 | C15: CAUÃ DA ROCHA SOUSA | D15: =B73 -> 4.5 | E15: B | F15: B | G15: A | H15: B | I15: B | J15: D | K15: C | L15: B | M15: C | N15: C | O15: E | P15: B | Q15: D | R15: B | S15: A | T15: ## | U15: D | V15: B | W15: E | X15: E
A16: 11 | B16: 07090733130 | C16: DANIEL CARVALHO DE OLIVEIRA | D16: =B74 -> 8 | E16: A | F16: B | G16: C | H16: B | I16: B | J16: A | K16: D | L16: D | M16: B | N16: C | O16: E | P16: B | Q16: D | R16: D | S16: C | T16: ## | U16: D | V16: B | W16: D | X16: B
A17: 12 | B17: 04047837164 | C17: DAVI TAVARES DE MORAIS | D17: =B75 -> 5 | E17: A | F17: D | G17: C | H17: C | I17: E | J17: B | K17: D | L17: B | M17: B | N17: D | O17: E | P17: B | Q17: A | R17: D | S17: D | T17: ## | U17: D | V17: B | W17: A | X17: C
A18: 13 | B18: 70967097118 | C18: ESTHER VARGAS DORNELES
A19: 14 | B19: 08970355189 | C19: GUSTAVO MACIEL LOPES | D19: =B77 -> 4 | E19: C | F19: B | G19: C | H19: A | I19: E | J19: C | K19: D | L19: C | M19: E | N19: B | O19: B | P19: B | Q19: D | R19: E | S19: D | T19: ## | U19: D | V19: B | W19: E | X19: E
A20: 15 | B20: 07965349183 | C20: HELLOA SAMILLE RODRIGUES DOS SANTOS | D20: =B78 -> 4.5 | E20: C | F20: B | G20: D | H20: B | I20: E | J20: A | K20: B | L20: C | M20: A | N20: B | O20: E | P20: B | Q20: D | R20: D | S20: C | T20: ## | U20: D | V20: B | W20: D | X20: B
A21: 16 | B21: 08543142105 | C21: HELOÍSA SOUZA FERNANDES | D21: =B79 -> 2.5 | E21: D | F21: C | G21: E | H21: B | I21: B | J21: C | K21: D | L21: C | M21: D | N21: A | O21: B | P21: E | Q21: B | R21: C | S21: E | T21: ## | U21: C | V21: D | W21: A | X21: A
A22: 17 | B22: 10237382105 | C22: HIASMIM BENTO DA SILVA | D22: =B80 -> 7.5 | E22: A | F22: B | G22: E | H22: B | I22: E | J22: B | K22: D | L22: D | M22: B | N22: C | O22: E | P22: B | Q22: D | R22: C | S22: C | T22: ## | U22: D | V22: E | W22: D | X22: E
A23: 18 | B23: 05536817108 | C23: HUGO BOAVENTURA SILVA ARAUJO | D23: =B81 -> 7 | E23: A | F23: B | G23: C | H23: B | I23: B | J23: A | K23: D | L23: B | M23: C | N23: C | O23: E | P23: B | Q23: D | R23: D | S23: C | T23: ## | U23: D | V23: E | W23: D | X23: E
A24: 19 | B24: 04760434178 | C24: ISABELLA SANTOS SEABRA | D24: =B82 -> 4 | E24: B | F24: A | G24: E | H24: B | I24: E | J24: C | K24: B | L24: D | M24: B | N24: A | O24: E | P24: B | Q24: C | R24: D | S24: A | T24: ## | U24: D | V24: B | W24: A | X24: C
A25: 20 | B25: 06718130133 | C25: JOÃO PEDRO DA SILVA OLIVEIRA | D25: =B83 -> 4.5 | E25: C | F25: B | G25: A | H25: B | I25: E | J25: A | K25: C | L25: D | M25: C | N25: B | O25: E | P25: B | Q25: D | R25: E | S25: D | T25: ## | U25: D | V25: B | W25: B | X25: B
A26: 21 | B26: 05403249141 | C26: KALEBE CARDIAL VIEIRA DOS SANTOS | D26: =B84 -> 5.5 | E26: B | F26: B | G26: D | H26: B | I26: B | J26: D | K26: E | L26: D | M26: B | N26: C | O26: B | P26: B | Q26: D | R26: D | S26: A | T26: ## | U26: D | V26: C | W26: A | X26: C
A27: 22 | B27: 09181820186 | C27: LETICIA MARÇAL OLIVEIRA
A28: 23 | B28: 11744134170 | C28: LIVIA NEVES DE SOUSA | D28: =B86 -> 4.5 | E28: D | F28: B | G28: B | H28: B | I28: E | J28: E | K28: A | L28: B | M28: B | N28: A | O28: E | P28: B | Q28: D | R28: B | S28: C | T28: ## | U28: D | V28: E | W28: B | X28: B
A29: 24 | B29: 07637161110 | C29: LUCAS ALVARO SILVA DOS SANTOS | D29: =B87 -> 3.5 | E29: C | F29: A | G29: A | H29: B | I29: B | J29: C | K29: C | L29: C | M29: B | N29: C | O29: B | P29: B | Q29: D | R29: B | S29: A | T29: ## | U29: E | V29: E | W29: E | X29: B
A30: 25 | B30: 09180723101 | C30: LUIZ GUSTAVO LOPES BERNARDES | D30: =B88 -> 7 | E30: A | F30: B | G30: C | H30: B | I30: B | J30: C | K30: E | L30: B | M30: B | N30: C | O30: E | P30: B | Q30: D | R30: D | S30: C | T30: ## | U30: D | V30: B | W30: D | X30: B
A31: 26 | B31: 06049557152 | C31: MANUELLA APARECIDA RODRIGUES DE LANA | D31: =B89 -> 5.5 | E31: A | F31: B | G31: E | H31: B | I31: B | J31: B | K31: E | L31: B | M31: D | N31: C | O31: A | P31: B | Q31: D | R31: C | S31: D | T31: ## | U31: D | V31: D | W31: E | X31: D
A32: 27 | B32: 04941410181 | C32: MARIA CLARA DE MENEZES MEDEIROS | D32: =B90 -> 4 | E32: C | F32: B | G32: A | H32: B | I32: E | J32: A | K32: B | L32: C | M32: D | N32: A | O32: E | P32: B | Q32: D | R32: A | S32: D | T32: ## | U32: D | V32: C | W32: D | X32: B
A33: 28 | B33: 05842410117 | C33: MARIA CLARA DOS SANTOS NICOLAU | D33: =B91 -> 4 | E33: C | F33: B | G33: E | H33: B | I33: E | J33: B | K33: A | L33: B | M33: C | N33: D | O33: C | P33: B | Q33: D | R33: C | S33: D | T33: ## | U33: D | V33: A | W33: E | X33: C
A34: 29 | B34: 07470130128 | C34: MARIA EDUARDA BASILIO LOPES | D34: =B92 -> 6.5 | E34: A | F34: B | G34: C | H34: B | I34: B | J34: B | K34: E | L34: D | M34: C | N34: C | O34: E | P34: B | Q34: D | R34: D | S34: A | T34: ## | U34: D | V34: E | W34: A | X34: E
A35: 30 | B35: 08164218111 | C35: MURILO ABREU NOGUEIRA | D35: =B93 -> 3 | E35: B | F35: A | G35: D | H35: B | I35: E | J35: D | K35: A | L35: D | M35: C | N35: B | O35: D | P35: B | Q35: D | R35: D | S35: D | T35: ## | U35: D | V35: B | W35: A | X35: B
A36: 31 | B36: 09542219156 | C36: NAYARA CORREIA GOMES | D36: =B94 -> 6 | E36: C | F36: B | G36: E | H36: B | I36: A | J36: B | K36: C | L36: D | M36: B | N36: B | O36: E | P36: B | Q36: D | R36: D | S36: C | T36: ## | U36: D | V36: B | W36: D | X36: E
A37: 32 | B37: 05540063163 | C37: PEDRO LUCAS QUEIROZ SOUZA | D37: =B95 -> 5 | E37: B | F37: B | G37: E | H37: D | I37: E | J37: B | K37: A | L37: D | M37: B | N37: A | O37: E | P37: B | Q37: D | R37: D | S37: C | T37: ## | U37: D | V37: B | W37: A | X37: B
A38: 33 | B38: 08691656158 | C38: RAFAEL DUTRA DA SILVA | D38: =B96 -> 3 | E38: D | F38: C | G38: E | H38: B | I38: B | J38: A | K38: C | L38: D | M38: D | N38: B | O38: C | P38: C | Q38: D | R38: B | T38: ## | U38: C | V38: D | W38: B | X38: D
A39: 34 | B39: 09316218101 | C39: RAMON ENZO RODIANE DE OLIVEIRA | D39: =B97 -> 4.5 | E39: B | F39: B | G39: C | H39: B | I39: C | J39: A | K39: D | L39: B | M39: B | N39: A | O39: A | P39: B | Q39: D | R39: B | S39: E | T39: ## | U39: D | V39: A | W39: C | X39: B
A40: 35 | B40: 08926685128 | C40: SAMUEL MENDES DE LIMA | D40: =B98 -> 5.5 | E40: B | F40: B | G40: D | H40: B | I40: E | J40: B | K40: C | L40: D | M40: A | N40: A | O40: E | P40: B | Q40: D | R40: E | S40: D | T40: ## | U40: D | V40: B | W40: D | X40: B
...

Sheet 3C
A1: 3C (35) | D1: NOTA | E1: SIMULADO SAEB MATEMÁTICA 01/09 (SEGUNDA-FEIRA)
A2: Nº | B2: CPF | C2: NOME | E2: 1 | F2: 2 | G2: 3 | H2: 4 | I2: 5 | J2: 6 | K2: 7 | L2: 8 | M2: 9 | N2: 10 | O2: 11 | P2: 12 | Q2: 13 | R2: 14 | S2: 15 | T2: 16 | U2: 17 | V2: 18 | W2: 19 | X2: 20
A3: 00 | B3: 00000000000 | C3: GABARITO | E3: A | F3: B | G3: C | H3: B | I3: B | J3: B | K3: D | L3: D | M3: B | N3: C | O3: E | P3: B | Q3: D | R3: E | S3: C | T3: ## | U3: D | V3: D | W3: D | X3: C
A4: VALORES | E4: 0.5 | F4: 0.5 | G4: 0.5 | H4: 0.5 | I4: 0.5 | J4: 0.5 | K4: 0.5 | L4: 0.5 | M4: 0.5 | N4: 0.5 | O4: 0.5 | P4: 0.5 | Q4: 0.5 | R4: 0.5 | S4: 0.5 | T4: 0.5 | U4: 0.5 | V4: 0.5 | W4: 0.5 | X4: 0.5
A5: TESTE | D5: =B61 -> 10 | E5: A | F5: B | G5: C | H5: B | I5: B | J5: B | K5: D | L5: D | M5: B | N5: C | O5: E | P5: B | Q5: D | R5: E | S5: C | T5: ## | U5: D | V5: D | W5: D | X5: C
A6: 1 | B6: 07677500129 | C6: ADRIELLY LOPES GOMES | D6: =B62 -> 3.5 | E6: B | F6: A | G6: D | H6: D | I6: C | J6: B | K6: D | L6: D | M6: E | N6: A | O6: B | P6: B | Q6: C | R6: B | S6: C | T6: ## | U6: B | V6: B | W6: D | X6: E
A7: 2 | B7: 08030821182 | C7: ANA CLARA HOZANA ANDRADE | D7: =B63 -> 5.5 | E7: A | F7: B | G7: A | H7: B | I7: B | J7: A | K7: E | L7: B | M7: D | N7: C | O7: D | P7: B | Q7: D | R7: D | S7: D | T7: ## | U7: D | V7: D | W7: D | X7: E
A8: 3 | B8: 08595023174 | C8: ANA CLARA SOARES DE ANDRADE | D8: =B64 -> 6 | E8: C | F8: B | G8: E | H8: B | I8: E | J8: C | K8: B | L8: D | M8: A | N8: C | O8: E | P8: B | Q8: D | R8: C | S8: C | T8: ## | U8: D | V8: E | W8: D | X8: C
A9: 4 | B9: 70724510133 | C9: ANA CLARA SOUZA DE OLIVEIRA | D9: =B65 -> 5.5 | E9: B | F9: B | G9: A | H9: B | I9: B | J9: E | K9: D | L9: D | M9: C | N9: A | O9: E | P9: B | Q9: D | R9: C | S9: C | T9: ## | U9: D | V9: C | W9: A | X9: E
A10: 5 | B10: 05734171131 | C10: ANA KAROLLYNA CLARAS MARTINS | D10: =B66 -> 4.5 | E10: C | F10: B | G10: B | H10: B | I10: A | J10: C | K10: A | L10: D | M10: B | N10: A | O10: E | P10: B | Q10: D | R10: C | S10: D | T10: ## | U10: D | V10: A | W10: E | X10: A
A11: 6 | B11: 06714872135 | C11: ARTHUR VITOR DA SILVA NEPOMUCENO | D11: =B67 -> 6.5 | E11: B | F11: B | G11: A | H11: B | I11: A | J11: D | K11: D | L11: D | M11: C | N11: C | O11: E | P11: B | Q11: D | R11: D | S11: C | T11: ## | U11: D | V11: B | W11: D | X11: C
A12: 7 | B12: 04073834177 | C12: ASSUELQUE ESTRELA DIAS | D12: =B68 -> 5.5 | E12: D | F12: B | G12: C | H12: B | I12: E | J12: C | K12: D | L12: D | M12: C | N12: E | O12: E | P12: B | Q12: D | R12: C | S12: C | T12: ## | U12: B | V12: B | W12: E | X12: C
A13: 8 | B13: 71200003144 | C13: DAVI DA COSTA COUTRIM | D13: =B69 -> 5 | E13: B | F13: B | G13: E | H13: B | I13: E | J13: C | K13: C | L13: D | M13: B | N13: C | O13: E | P13: B | Q13: D | R13: D | S13: D | T13: ## | U13: D | V13: B | W13: B | X13: E
A14: 9 | B14: 70529823152 | C14: EDUARDO KISLEY PEREIRA COSTANTIN DOS SANTOS | D14: =B70 -> 5 | E14: A | F14: A | G14: D | H14: B | I14: E | J14: B | K14: D | L14: C | M14: B | N14: B | O14: E | P14: B | Q14: C | R14: A | S14: A | T14: ## | U14: D | V14: B | W14: D | X14: B
A15: 10 | B15: 05900769143 | C15: FERNANDA ALVES FERREIRA | D15: =B71 -> 3 | E15: D | F15: B | G15: A | H15: B | I15: C | J15: A | K15: E | L15: C | M15: C | N15: C | O15: B | P15: B | Q15: D | R15: A | S15: D | T15: ## | U15: C | V15: B | W15: B | X15: A
A16: 11 | B16: 13925126708 | C16: GABRIEL MEDEIROS COSTA E SILVA | D16: =B72 -> 5.5 | F16: B | G16: A | H16: B | I16: A | J16: A | K16: C | L16: D | M16: B | O16: E | P16: B | Q16: D | R16: D | S16: C | T16: ## | U16: D | V16: B | W16: A | X16: C
A17: 12 | B17: 05200809126 | C17: ISABELLI FERREIRA VASCO | D17: =B73 -> 3 | E17: C | F17: D | G17: B | H17: B | I17: E | J17: D | K17: D | L17: C | M17: D | N17: B | O17: A | P17: B | Q17: C | R17: A | S17: D | T17: ## | U17: D | V17: D | W17: A | X17: B
A18: 13 | B18: 06199841123 | C18: JOÃO HENRIQUE LEITE CAMPOS | D18: =B74 -> 2 | E18: E | F18: C | G18: E | H18: D | I18: E | J18: A | K18: C | L18: C | M18: D | N18: A | O18: A | P18: A | Q18: D | R18: C | S18: D | T18: ## | U18: D | V18: D | W18: A | X18: B
A19: 14 | B19: 07741447181 | C19: JORLANDO GABRIEL OLIVEIRA LEAL | D19: =B75 -> 5 | E19: D | F19: B | G19: B | H19: B | I19: C | J19: A | K19: E | L19: D | M19: C | N19: C | O19: D | P19: B | Q19: D | R19: D | S19: C | T19: ## | U19: D | V19: B | W19: D | X19: B
A20: 15 | B20: 09173244120 | C20: KAIO RAUAN DA SILVA MATIAS | D20: =B76 -> 5 | E20: D | F20: B | H20: C | I20: B | J20: B | K20: A | L20: B | M20: B | N20: B | O20: E | P20: B | Q20: D | R20: D | S20: A | T20: ## | U20: D | V20: A | W20: D | X20: B
A21: 16 | B21: 07955540107 | C21: KAUA PEREIRA RODRIGUES DOS SANTOS | D21: =B77 -> 4.5 | E21: B | F21: B | G21: A | H21: B | I21: E | J21: D | K21: B | L21: C | M21: B | N21: C | O21: A | P21: B | Q21: D | R21: D | S21: C | T21: ## | U21: B | V21: D | W21: B | X21: B
A22: 17 | B22: 07474283107 | C22: KESIA REIS DE ALBUQUERQUE | D22: =B78 -> 5.5 | E22: C | F22: B | G22: A | H22: B | I22: E | J22: B | K22: D | L22: D | M22: B | N22: C | O22: D | P22: B | Q22: E | R22: C | S22: D | T22: ## | U22: D | V22: B | W22: D | X22: A
A23: 18 | B23: 08884095166 | C23: LETICIA LIZ BENIGNO DA SILVA | D23: =B79 -> 5 | E23: C | F23: B | G23: A | H23: C | I23: B | J23: D | K23: E | L23: C | M23: B | N23: E | O23: E | P23: B | Q23: D | R23: E | S23: D | T23: ## | U23: D | V23: B | W23: D | X23: B
A24: 19 | B24: 07981900190 | C24: LÍDIA VIANA DE LIMA | D24: =B80 -> 5.5 | E24: B | F24: B | G24: C | H24: B | I24: A | J24: B | K24: C | L24: D | M24: B | N24: C | O24: E | P24: B | Q24: D | R24: D | S24: A|D | T24: ## | U24: B | V24: E | W24: B | X24: B
A25: 20 | B25: 08644553135 | C25: LORRANE GABRIELE ALVES DE JESUS | D25: =B81 -> 3.5 | E25: D | F25: B | G25: D | H25: B | I25: C | J25: A | K25: C | L25: C | M25: D | N25: D | O25: E | P25: B | Q25: D | R25: B | S25: D | T25: ## | U25: D | V25: B | W25: A | X25: B
A26: 21 | B26: 10338435476 | C26: LUCAS MENDES DE ALCANTARA NASCIMENTO | D26: =B82 -> 5 | E26: B | F26: B | G26: E | H26: A | I26: E | J26: C | K26: D | L26: D | M26: A | N26: B | O26: E | P26: B | Q26: D | R26: D | S26: C | T26: ## | U26: D | V26: B | W26: D | X26: B
A27: 22 | B27: 05468673169 | C27: LUÍSA DIAS CUNHA | D27: =B83 -> 7 | E27: C | F27: B | G27: B | H27: B | I27: C | J27: B | K27: D | L27: D | M27: A | N27: C | O27: E | P27: B | Q27: D | R27: B | S27: A | T27: ## | U27: D | V27: D | W27: D | X27: C
A28: 23 | B28: 06635007105 | C28: LUIS FELIPE ALVES DOS REIS | D28: =B84 -> 4 | E28: E | F28: B | G28: D | H28: B | I28: E | J28: A | K28: D | L28: C | M28: D | N28: D | O28: B | P28: B | Q28: D | R28: C | S28: D | T28: ## | U28: C | V28: D | W28: C | X28: C
A29: 24 | B29: 06938667136 | C29: MANUELA GOMES DA SILVA | D29: =B85 -> 5.5 | E29: D | F29: B | G29: C | H29: B | I29: D | J29: C | K29: D | L29: E | M29: B | N29: C | O29: E | P29: B | Q29: D | R29: B | S29: A | T29: ## | U29: D | V29: C | W29: B | X29: E
A30: 25 | B30: 08949922100 | C30: MARIA CLARA ALVES TEIXEIRA COSTA | D30: =B86 -> 3 | E30: D | F30: A | G30: A | H30: A | I30: E | J30: B | K30: A | L30: B | M30: D | N30: C | O30: E | P30: B | Q30: C | R30: D | S30: D | T30: ## | U30: D | V30: C | W30: A | X30: A
A31: 26 | B31: 09573902117 | C31: MARIA CLARA CUNHA AGUIAR | D31: =B87 -> 5.5 | E31: B | F31: B | G31: B | H31: B | I31: E | J31: B | K31: C | L31: D | M31: B | N31: C | O31: C | P31: B | Q31: C | R31: D | S31: C | T31: ## | U31: D | V31: D | W31: A | X31: E
A32: 27 | B32: 09134376119 | C32: MATHEUS CUTRIM ARRUDA
A33: 28 | B33: 04250255190 | C33: MIRELY XAVIER DE SOUZA RODRIGUES | D33: =B89 -> 5 | E33: D | F33: B | G33: C | H33: B | I33: A | J33: C | K33: D | L33: C | M33: A | N33: E | O33: E | P33: B | Q33: D | R33: D | S33: C | T33: ## | U33: D | V33: B | W33: C | X33: B
A34: 29 | B34: 06477528169 | C34: MURILO VINÍCIUS MELO SANTANA | D34: =B90 -> 3.5 | E34: D | F34: B | G34: D | H34: B | I34: E | J34: A | K34: D | L34: C | M34: A | N34: B | O34: E | P34: B | Q34: C | R34: C | S34: D | T34: ## | U34: D | V34: B | W34: B | X34: E
A35: 30 | B35: 08992692145 | C35: PEDRO HENRIQUE EDUARDO RIBEIRO COSTA | D35: =B91 -> 5 | E35: D | F35: B | G35: A | H35: B | I35: B | J35: E | K35: D | L35: D | M35: A | N35: C | O35: B | P35: B | Q35: D | R35: B | S35: A | T35: ## | U35: D | V35: B | W35: E | X35: B
A36: 31 | B36: 06335082179 | C36: RAFAELA BARROS OLIVEIRA | D36: =B92 -> 5.5 | E36: A | F36: B | G36: A | H36: B | I36: E | J36: C | K36: C | L36: B | M36: C | N36: C | O36: E | P36: B | Q36: D | R36: B | S36: C | T36: ## | U36: D | V36: D | W36: A | X36: B
A37: 32 | B37: 06085402180 | C37: SARA ESTEFANY CARVALHO FERNANDES | D37: =B93 -> 2.5 | E37: C | F37: C | G37: A | H37: B | I37: C | J37: C | K37: C | L37: C | M37: E | N37: A | O37: C | P37: B | Q37: D | R37: C | S37: C | T37: ## | U37: B | V37: B | W37: E | X37: E
A38: 33 | B38: 04462260171 | C38: SARA VITÓRIA DE OLIVEIRA | D38: =B94 -> 4.5 | E38: E | F38: B | G38: E | H38: B | I38: E | J38: B | K38: C | L38: C | M38: A | N38: D | O38: E | P38: B | Q38: C | R38: B | S38: C | T38: ## | U38: D | V38: C | W38: D | X38: A
A39: 34 | B39: 11134939175 | C39: STEPHANY SANTANA DE ARAUJO | D39: =B95 -> 5.5 | E39: C | F39: A | G39: D | H39: B | I39: B | J39: A | K39: C | L39: D | M39: B | N39: A | O39: E | P39: B | Q39: D | R39: D | S39: C | T39: ## | U39: D | V39: D | W39: E | X39: E
A40: 35 | B40: 10037260111 | C40: VINICIUS CASTRO MARTINS | D40: =B96 -> 3.5 | E40: C | F40: B | G40: A | H40: B | I40: B | J40: E | K40: C | L40: D | M40: C | N40: A | O40: D | P40: B | Q40: D | R40: B | S40: D | T40: ## | U40: C | V40: B | W40: A | X40: B
...

Sheet 3D
A1: 3D (32) | D1: NOTA | E1: SIMULADO SAEB MATEMÁTICA 01/09 (SEGUNDA-FEIRA)
A2: Nº | B2: CPF | C2: NOME | E2: 1 | F2: 2 | G2: 3 | H2: 4 | I2: 5 | J2: 6 | K2: 7 | L2: 8 | M2: 9 | N2: 10 | O2: 11 | P2: 12 | Q2: 13 | R2: 14 | S2: 15 | T2: 16 | U2: 17 | V2: 18 | W2: 19 | X2: 20
A3: 00 | B3: 00000000000 | C3: GABARITO | E3: A | F3: B | G3: C | H3: B | I3: B | J3: B | K3: D | L3: D | M3: B | N3: C | O3: E | P3: B | Q3: D | R3: E | S3: C | T3: ## | U3: D | V3: D | W3: D | X3: C
A4: VALORES | E4: 0.5 | F4: 0.5 | G4: 0.5 | H4: 0.5 | I4: 0.5 | J4: 0.5 | K4: 0.5 | L4: 0.5 | M4: 0.5 | N4: 0.5 | O4: 0.5 | P4: 0.5 | Q4: 0.5 | R4: 0.5 | S4: 0.5 | T4: 0.5 | U4: 0.5 | V4: 0.5 | W4: 0.5 | X4: 0.5
A5: TESTE | D5: =B60 -> 10 | E5: A | F5: B | G5: C | H5: B | I5: B | J5: B | K5: D | L5: D | M5: B | N5: C | O5: E | P5: B | Q5: D | R5: E | S5: C | T5: ## | U5: D | V5: D | W5: D | X5: C
A6: 1 | B6: 08885732194 | C6: ANA CLARA ALVES CARACIOLA CAVALCANTE | D6: =B61 -> 6 | E6: A | F6: B | G6: B | H6: B | I6: A | J6: A | K6: D | L6: D | M6: B | N6: C | O6: E | P6: B | Q6: D | R6: A | S6: C | T6: C | U6: D | V6: E | W6: E | X6: B
A7: 2 | B7: 09763628130 | C7: ANA LUIZA DE SOUZA BRITO
A8: 3 | B8: 09123634103 | C8: ANNA VITÓRIA LOPES SOUZA | D8: =B63 -> 5.5 | E8: B | F8: B | G8: E | H8: B | I8: D | J8: C | K8: C | L8: D | M8: B | N8: C | O8: E | P8: B | Q8: D | S8: C | U8: D | V8: D | W8: E | X8: B
A9: 4 | B9: 70532963180 | C9: BIANCA RODRIGUES DA SILVA | D9: =B64 -> 3.5 | E9: B | F9: A | G9: E | H9: B | I9: E | J9: A | K9: C | L9: D | M9: C | N9: D | O9: C | P9: B | Q9: D | R9: A | S9: D | T9: E | U9: D | V9: C | W9: D | X9: C
A10: 5 | B10: 08577681157 | C10: CLARA MACENA DA SILVA
A11: 6 | B11: 10997847190 | C11: DIEGO GRANGEIRO MOREIRA | D11: =B66 -> 5 | E11: B | F11: B | G11: C | H11: B | I11: E | J11: D | K11: D | L11: D | M11: B | N11: A | O11: E | P11: B | Q11: D | R11: C | S11: D | T11: B | U11: D | V11: B | W11: E | X11: B
A12: 7 | B12: 08841360194 | C12: EDUARDA FERNANDES SEABRA | D12: =B67 -> 4.5 | E12: C | F12: A | G12: E | H12: B | I12: E | J12: B | K12: D | L12: C | M12: B | N12: C | O12: E | P12: B | Q12: C | R12: D | S12: D | T12: A | U12: D | V12: B | W12: E | X12: C
A13: 8 | B13: 07667106100 | C13: GABRIELY KAROLAYNE PEREIRA DO NASCIMENTO | D13: =B68 -> 2.5 | E13: C | F13: B | G13: E | H13: B | I13: E | J13: C | K13: E | L13: A | M13: B | N13: B | O13: E | P13: B | Q13: C | R13: C | S13: B | T13: D | U13: B | V13: E | W13: E | X13: D
A14: 9 | B14: 08393148170 | C14: GRAZIELA MARINS QUINTINO DE BRITTO
A15: 10 | B15: 10419673148 | C15: GUILHERME DAVI TÁVORA JACQUES RESENDE | D15: =B70 -> 4.5 | E15: A | F15: C | G15: C | H15: B | I15: A | J15: D | K15: C | L15: D | M15: D | N15: A | O15: E | P15: B | Q15: D | R15: B | S15: C | T15: B | U15: D | V15: A | W15: E | X15: B
A16: 11 | B16: 09038282192 | C16: GUSTAVO BAPTISTA SOFIA | D16: =B71 -> 2.5 | E16: E | F16: B | G16: B | H16: B | I16: E | J16: D | K16: C | L16: B | M16: A | N16: A | O16: B | P16: B | Q16: C | R16: D | S16: C | T16: B | U16: C | V16: E | W16: D | X16: A
A17: 12 | B17: 09182701113 | C17: HELOISA DE OLIVEIRA DA SILVA | D17: =B72 -> 5.5 | E17: C | F17: B | G17: C | H17: B | I17: C | J17: C | K17: A | L17: D | M17: B | N17: C | O17: E | P17: B | Q17: D | R17: E | S17: A | T17: B | U17: D | V17: B | W17: E | X17: B
A18: 13 | B18: 11583109609 | C18: HICARO GOMES CAMARGOS | D18: =B73 -> 4 | E18: E | F18: A | G18: A | H18: B | I18: E | J18: B | K18: D | L18: C | M18: D | N18: C | O18: D | P18: B | Q18: D | R18: A | S18: D | T18: C | U18: D | V18: E | W18: B | X18: C
A19: 14 | B19: 05888528137 | C19: ISABELY VIEIRA DANTAS | D19: =B74 -> 5 | E19: D | F19: B | G19: E | H19: B | I19: E | J19: E | K19: C | L19: E | M19: B | N19: A | O19: E | P19: B | Q19: D | R19: D | S19: C | T19: E | U19: D | V19: D | W19: D | X19: A
A20: 15 | B20: 07718379175 | C20: JOÃO EMANUEL ALVES PINHEIRO | D20: =B75 -> 7.5 | E20: A | F20: B | G20: E | H20: B | I20: B | J20: A | K20: D | L20: D | M20: B | N20: C | O20: E | P20: B | Q20: D | R20: E | S20: C | T20: B | U20: D | V20: B | W20: D | X20: E
A21: 16 | B21: 04487071100 | C21: JOÃO PEDRO GUIMARÃES GUEDES | D21: =B76 -> 5 | E21: C | F21: C | G21: B | H21: B | I21: B | J21: D | K21: A | L21: D | M21: E | N21: C | O21: E | P21: B | Q21: D | R21: D | S21: B | T21: B | U21: D | V21: D | W21: D | X21: B
A22: 17 | B22: 03852992141 | C22: JOAO PEDRO MOREIRA MOTA | D22: =B77 -> 4.5 | E22: A | F22: B | G22: B | H22: B | I22: E | J22: C | K22: D | L22: B | M22: C | N22: A | O22: E | P22: B | Q22: D | R22: D | S22: A | T22: C | U22: D | V22: B | W22: D | X22: B
A23: 18 | B23: 07414640124 | C23: JÚLIA GABRIELA DA SILVA SANTOS | D23: =B78 -> 6 | E23: B | F23: B | G23: D | H23: B | I23: A | J23: A | K23: D | L23: D | M23: B | N23: C | O23: E | P23: B | Q23: D | R23: D | S23: C | T23: C | U23: D | V23: E | W23: D | X23: E
A24: 19 | B24: 10432390146 | C24: KAUAN GOMES DE AMORIM LEAL | D24: =B79 -> 4.5 | E24: B | F24: A | G24: B | H24: B | I24: E | J24: C | K24: D | L24: D | M24: B | N24: C | O24: C | P24: B | Q24: D | R24: A | S24: A | T24: D | U24: D | V24: D | W24: B | X24: B
A25: 20 | B25: 08951431193 | C25: KAUÊ LUIGGI SILVEIRA ALVES DOS SANTOS | D25: =B80 -> 4.5 | E25: C | F25: B | G25: D | H25: B | I25: A | J25: A | K25: B | L25: B | M25: B | N25: C | O25: E | P25: B | Q25: D | R25: D | S25: C | T25: B | U25: B | V25: E | W25: A | X25: C
A26: 21 | B26: 07504814121 | C26: KETELEM YASMIM DE FRANÇA ROCHA | D26: =B81 -> 4 | E26: B | F26: A | G26: E | H26: B | I26: E | J26: B | K26: D | L26: C | M26: B | N26: C | O26: E | P26: B | Q26: C | R26: D | S26: A | T26: A | U26: D | V26: B | W26: E | X26: A
A27: 22 | B27: 05955524126 | C27: KEVEN CRISTIAN AMANCIO BARBOSA | D27: =B82 -> 6 | E27: B | F27: B | G27: D | H27: B | I27: B | J27: E | K27: D | L27: D | M27: B | N27: C | O27: E | P27: B | Q27: D | R27: D | S27: C | T27: A | U27: B | V27: B | W27: C | X27: C
A28: 23 | B28: 05998562119 | C28: LAIS DE CASTRO FERNANDES | D28: =B83 -> 4 | E28: A | F28: B | G28: A | H28: B | I28: E | K28: A | L28: C | M28: D | O28: E | P28: B | Q28: D | S28: C | U28: D | V28: E | W28: E | X28: B
A29: 24 | B29: 08851770107 | C29: LARISSA RODRIGUES COELHO | D29: =B84 -> 3 | E29: B | F29: B | G29: D | H29: B | I29: A | J29: B | K29: C | L29: B | M29: B | N29: E | O29: E | P29: B | Q29: C | R29: B | S29: B | T29: B | U29: B | V29: B | W29: B | X29: B
A30: 25 | B30: 05782974184 | C30: LUIS CARLOS FERREIRA DE SOUSA | D30: =B85 -> 5.5 | E30: B | F30: B | G30: C | H30: B | I30: C | J30: B | K30: A | L30: D | M30: B | N30: A | O30: E | P30: B | Q30: D | R30: D | S30: C | T30: A | U30: D | V30: B | W30: C | X30: B
A31: 26 | B31: 08724294152 | C31: MARIA EDUARDA DE JESUS SERAFIM | D31: =B86 -> 5 | E31: A | F31: B | G31: B | H31: B | I31: A | J31: A | K31: D | L31: D | M31: B | N31: C | O31: E | P31: B | Q31: D | R31: B | S31: D | T31: D | U31: B | V31: E | W31: B | X31: D
A32: 27 | B32: 07579097109 | C32: MARIA LUIZA VIEIRA DE SOUSA | D32: =B87 -> 4 | E32: C | F32: B | G32: D | H32: B | I32: A | J32: A | K32: B | L32: B | M32: B | N32: C | O32: E | P32: B | Q32: D | R32: C | S32: D | T32: B | U32: B | V32: E | W32: A | X32: C
A33: 28 | B33: 05732941193 | C33: MILENA ROCHA MOREIRA | D33: =B88 -> 4 | E33: A | F33: B | G33: D | H33: B | I33: C | J33: A | K33: C | L33: B | M33: D | N33: B | O33: E | P33: B | Q33: C | R33: B | S33: D | T33: D | U33: D | V33: D | W33: D | X33: D
A34: 29 | B34: 04716939103 | C34: NICOLAS DE OLIVEIRA NASCIMENTO | D34: =B89 -> 4.5 | E34: E | F34: A | G34: E | H34: B | I34: D | J34: D | K34: A | L34: D | M34: B | N34: C | O34: E | P34: B | Q34: C | R34: A | S34: C | T34: E | U34: D | V34: D | W34: E | X34: B
A35: 30 | B35: 09809895151 | C35: PEDRO MIGUEL MADEIRA FLORES | D35: =B90 -> 3.5 | E35: B | F35: A | G35: D | H35: E | I35: C | J35: B | K35: D | L35: B | M35: A | N35: A | O35: E | P35: B | Q35: D | R35: D | S35: C | T35: A | U35: D | V35: B | W35: A | X35: D
A36: 31 | B36: 08601423108 | C36: RAFAEL MATA MADERA SAMPAIO | D36: =B91 -> 3.5 | E36: D | F36: B | G36: C | H36: E | I36: E | J36: D | K36: E | L36: D | M36: A | N36: A | O36: D | P36: B | Q36: D | R36: B | S36: A | T36: D | U36: D | V36: B | W36: D | X36: E
A37: 32 | B37: 42879285801 | C37: SAMUEL ABNER GOMES IIZUKA | D37: =B92 -> 6.5 | E37: B | F37: B | G37: A | H37: B | I37: B | J37: A | K37: D | L37: D | M37: B | N37: C | O37: E | P37: B | Q37: D | R37: C | S37: C | T37: A | U37: D | V37: B | W37: D | X37: B
A38: 33 | B38: 07660615157 | C38: SARAH GOMES ALVES | D38: =B93 -> 6.5 | E38: A | F38: B | G38: A | H38: B | I38: B | J38: A | K38: D | L38: D | M38: B | N38: E | O38: E | P38: B | Q38: D | R38: D | S38: C | T38: B | U38: D | V38: B | W38: D | X38: E
A39: 34 | B39: 05816646125 | C39: VINICIUS PONTES BRITO | D39: =B94 -> 4 | E39: A | F39: B | G39: D | H39: B | I39: E | J39: B | K39: D | L39: B | M39: B | N39: C | O39: D | P39: C | Q39: C | R39: D | S39: D | T39: C | U39: B | V39: B | W39: E | X39: C
A40: 35 | B40: 07893589132 | C40: WENDEL BENICIO DOS SANTOS SILVA | D40: =B95 -> 5.5 | E40: C | F40: B | G40: A | H40: B | I40: D | J40: C | K40: D | L40: B | M40: B | N40: C | O40: E | P40: A | Q40: D | R40: E | S40: C | T40: C | U40: E | V40: B | W40: D | X40: C
...
